Workbook

Sheet Introduction
A1: Direct Measurements of COs & POs
A3: - This tool has been prepared to calculate the Course Outcomes (COs) & Program Outcomes (POs) for an Outcome Based Education (OBE) program.
A5: - There are only four spreadsheets (namely – Course Info, Marks, COs-POs & Report) where the user must enter the required data in the yellow cells only.
A7: Basic Instructions:
A9: "Course Info" | B9: Contain general information related to the course, the COs & the CO-PO mapping
A11: "Marks" | B11: The marks for the course should be based on the total mark (i.e. 100) assigned officially
A13: “CO-PO” | B13: COs & POs are calculated in this sheet. The instructor can enter the Target Pass Marks, Key Performance Indicator (KPI) for COs & POs.
A15: "REPORT" | B15: The sheet will generate a report with the COs & POs.
A17: Prepared by:
A19: Hasan Abdullah
A20: Lecturer
A21: Department of Computer Science and Technology
A22: Bangladesh Army International University of Science and Technology
A23: Sydpur, Cumilla
A24: Phone: +8801681523656
A25: E-mail: hasan.cse@baiust.ac.bd

Sheet Course Info
A1: Course Related Information
A2: (Please only enter information in the yellow cells)
B4: Course Code: | C4: CSE 213
B5: Course Title: | C5: Object Oriented Programming Language
B6: Department: | C6: Computer Science and Engineering
B7: Academic Year | C7: 2
B8: Semester | C8: 1
B9: Section | C9: A
B11: Course Outcomes (Cos)
B13: CO1 | C13: Students will be able to classify and apply major object-oriented concepts such as data abstraction, encapsulation, polymorphism, and inheritance.
B14: CO2 | C14: Students will solve various programming problems using C++ features like templates, exceptions, casting, operator overloads, dynamic memory allocation, modularity, I/O, and file I/O.
B15: CO3 | C15: Students will work in groups on presentations and assignments to develop teamwork and collaborative skills.
B16: CO4 | C16: Students will replicate and apply object-oriented software engineering concepts to solve real-life problems.
B17: CO5
B18: CO6
B19: CO7
B20: CO8
B21: CO9
B22: CO10
B24: * Mapping of COs with POs
C26: Engineering knowledge | D26: Problem analysis | E26: Design/development of solutions | F26: Investigation | G26: Modern tool usage | H26: The engineer and society | I26: Environment & sustainability | J26: Ethics | K26: Individual work and teamwork | L26: Communication | M26: Project management and finance | N26: Life-long learning
C27: PO1 | D27: PO2 | E27: PO3 | F27: PO4 | G27: PO5 | H27: PO6 | I27: PO7 | J27: PO8 | K27: PO9 | L27: PO10 | M27: PO11 | N27: PO12
B28: CO1 | C28: 1
B29: CO2 | D29: 1
B30: CO3 | K30: 1
B31: CO4 | D31: 1
B32: CO5
B33: CO6
B34: CO7
B35: CO8
B36: CO9
B37: CO10
B38: CO11
B39: CO12
C40: =SUM(C28:C39) -> 1 | D40: =SUM(D28:D39) -> 2 | E40: =SUM(E28:E39) -> 0 | F40: =SUM(F28:F39) -> 0 | G40: =SUM(G28:G39) -> 0 | H40: =SUM(H28:H39) -> 0 | I40: =SUM(I28:I39) -> 0 | J40: =SUM(J28:J39) -> 0 | ... N40: =SUM(N28:N39) -> 0

Sheet Marks
A1: Assessment Marks Obtained by the Students
A2: (Please only enter information in the yellow cells)
E5: 1 | F5: 2 | G5: 3 | H5: 4 | I5: 5 | J5: 6 | K5: 7 | L5: 8 | M5: 9 | N5: 10 | O5: 11 | P5: 12 | Q5: 13 | R5: 14 | S5: 15 | T5: 16 | U5: 17 | V5: 18 | W5: 19 | X5: 20 | Y5: 21 | Z5: 22 | AA5: 23 | AB5: 24 | AC5: 25 | AD5: 26 | AE5: 27 | AF5: 28 | AG5: 29 | AH5: 30 | AI5: 31 | AJ5: 32 | AK5: 33 | AL5: 34 | AM5: 35 | AN5: 36 | AO5: 37 | AP5: 38 | AQ5: 39 | AR5: 40 | AS5: 41 | AT5: 42 | AU5: 43 | AV5: 44 | AW5: 45 | AX5: 46 | AY5: 47 | AZ5: 48 | BA5: 49 | BB5: 50
D6: CO1 | E6: =IF(E$24=1,E$23,0) -> 10 | F6: =IF(F$24=1,F$23,0) -> 10 | G6: =IF(G$24=1,G$23,0) -> 0 | H6: =IF(H$24=1,H$23,0) -> 0 | I6: =IF(I$24=1,I$23,0) -> 0 | J6: =IF(J$24=1,J$23,0) -> 0 | K6: =IF(K$24=1,K$23,0) -> 30 | L6: =IF(L$24=1,L$23,0) -> 0 | ... P6: =IF(P$24=1,P$23,0) -> 30 | Q6: 0 | R6: =IF(R$24=1,R$23,0) -> 0 | S6: =IF(S$24=1,S$23,0) -> 0 | T6: =IF(T$24=1,T$23,0) -> 0 | U6: =IF(U$24=1,U$23,0) -> 0 | V6: =IF(V$24=1,V$23,0) -> 0 | W6: =IF(W$24=1,W$23,0) -> 0 | X6: =IF(X$24=1,X$23,0) -> 0 | Y6: =IF(Y$24=1,Y$23,0) -> 0 | ... BB6: =IF(BB$24=1,BB$23,0) -> 0 | BC6: =SUM(E6:BB6) -> 140
D7: CO2 | E7: =IF(E$24=2,E$23,0) -> 0 | F7: =IF(F$24=2,F$23,0) -> 0 | G7: =IF(G$24=2,G$23,0) -> 10 | H7: =IF(H$24=2,H$23,0) -> 0 | I7: =IF(I$24=2,I$23,0) -> 0 | J7: =IF(J$24=2,J$23,0) -> 10 | K7: =IF(K$24=2,K$23,0) -> 0 | L7: =IF(L$24=2,L$23,0) -> 0 | ... P7: =IF(P$24=2,P$23,0) -> 0 | Q7: 0 | R7: =IF(R$24=2,R$23,0) -> 30 | S7: =IF(S$24=2,S$23,0) -> 0 | T7: =IF(T$24=2,T$23,0) -> 0 | U7: =IF(U$24=2,U$23,0) -> 0 | V7: =IF(V$24=2,V$23,0) -> 0 | W7: =IF(W$24=2,W$23,0) -> 0 | X7: =IF(X$24=2,X$23,0) -> 0 | Y7: =IF(Y$24=2,Y$23,0) -> 0 | ... BB7: =IF(BB$24=2,BB$23,0) -> 0 | BC7: =SUM(E7:BB7) -> 50
D8: CO3 | E8: =IF(E$24=3,E$23,0) -> 0 | F8: =IF(F$24=3,F$23,0) -> 0 | G8: =IF(G$24=3,G$23,0) -> 0 | H8: =IF(H$24=3,H$23,0) -> 10 | I8: =IF(I$24=3,I$23,0) -> 0 | J8: =IF(J$24=3,J$23,0) -> 0 | K8: =IF(K$24=3,K$23,0) -> 0 | L8: =IF(L$24=3,L$23,0) -> 0 | ... P8: =IF(P$24=3,P$23,0) -> 0 | Q8: 0 | R8: =IF(R$24=3,R$23,0) -> 0 | S8: =IF(S$24=3,S$23,0) -> 0 | T8: =IF(T$24=3,T$23,0) -> 0 | U8: =IF(U$24=3,U$23,0) -> 0 | V8: =IF(V$24=3,V$23,0) -> 0 | W8: =IF(W$24=3,W$23,0) -> 0 | X8: =IF(X$24=3,X$23,0) -> 0 | Y8: =IF(Y$24=3,Y$23,0) -> 0 | ... BB8: =IF(BB$24=3,BB$23,0) -> 0 | BC8: =SUM(E8:BB8) -> 10
D9: CO4 | E9: =IF(E$24=4,E$23,0) -> 0 | F9: =IF(F$24=4,F$23,0) -> 0 | G9: =IF(G$24=4,G$23,0) -> 0 | H9: =IF(H$24=4,H$23,0) -> 0 | I9: =IF(I$24=4,I$23,0) -> 0 | J9: =IF(J$24=4,J$23,0) -> 0 | K9: =IF(K$24=4,K$23,0) -> 0 | L9: =IF(L$24=4,L$23,0) -> 30 | ... P9: =IF(P$24=4,P$23,0) -> 0 | Q9: 0 | R9: =IF(R$24=4,R$23,0) -> 0 | S9: =IF(S$24=4,S$23,0) -> 0 | T9: =IF(T$24=4,T$23,0) -> 0 | U9: =IF(U$24=4,U$23,0) -> 0 | V9: =IF(V$24=4,V$23,0) -> 0 | W9: =IF(W$24=4,W$23,0) -> 0 | X9: =IF(X$24=4,X$23,0) -> 0 | Y9: =IF(Y$24=4,Y$23,0) -> 0 | ... BB9: =IF(BB$24=4,BB$23,0) -> 0 | BC9: =SUM(E9:BB9) -> 60
D10: CO5 | E10: =IF(E$24=5,E$23,0) -> 0 | F10: =IF(F$24=5,F$23,0) -> 0 | G10: =IF(G$24=5,G$23,0) -> 0 | H10: =IF(H$24=5,H$23,0) -> 0 | I10: =IF(I$24=5,I$23,0) -> 0 | J10: =IF(J$24=5,J$23,0) -> 0 | K10: =IF(K$24=5,K$23,0) -> 0 | L10: =IF(L$24=5,L$23,0) -> 0 | ... P10: =IF(P$24=5,P$23,0) -> 0 | Q10: 0 | R10: =IF(R$24=5,R$23,0) -> 0 | S10: =IF(S$24=5,S$23,0) -> 0 | T10: =IF(T$24=5,T$23,0) -> 0 | U10: =IF(U$24=5,U$23,0) -> 0 | V10: =IF(V$24=5,V$23,0) -> 0 | W10: =IF(W$24=5,W$23,0) -> 0 | X10: =IF(X$24=5,X$23,0) -> 0 | Y10: =IF(Y$24=5,Y$23,0) -> 0 | ... BB10: =IF(BB$24=5,BB$23,0) -> 0 | BC10: =SUM(E10:BB10) -> 0
D11: CO6 | E11: =IF(E$24=6,E$23,0) -> 0 | F11: =IF(F$24=6,F$23,0) -> 0 | G11: =IF(G$24=6,G$23,0) -> 0 | H11: =IF(H$24=6,H$23,0) -> 0 | I11: =IF(I$24=6,I$23,0) -> 0 | J11: =IF(J$24=6,J$23,0) -> 0 | K11: =IF(K$24=6,K$23,0) -> 0 | L11: =IF(L$24=6,L$23,0) -> 0 | ... P11: =IF(P$24=6,P$23,0) -> 0 | Q11: 0 | R11: =IF(R$24=6,R$23,0) -> 0 | S11: =IF(S$24=6,S$23,0) -> 0 | T11: =IF(T$24=6,T$23,0) -> 0 | U11: =IF(U$24=6,U$23,0) -> 0 | V11: =IF(V$24=6,V$23,0) -> 0 | W11: =IF(W$24=6,W$23,0) -> 0 | X11: =IF(X$24=6,X$23,0) -> 0 | Y11: =IF(Y$24=6,Y$23,0) -> 0 | ... BB11: =IF(BB$24=6,BB$23,0) -> 0 | BC11: =SUM(E11:BB11) -> 0
D12: CO7 | E12: =IF(E$24=7,E$23,0) -> 0 | F12: =IF(F$24=7,F$23,0) -> 0 | G12: =IF(G$24=7,G$23,0) -> 0 | H12: =IF(H$24=7,H$23,0) -> 0 | I12: =IF(I$24=7,I$23,0) -> 0 | J12: =IF(J$24=7,J$23,0) -> 0 | K12: =IF(K$24=7,K$23,0) -> 0 | L12: =IF(L$24=7,L$23,0) -> 0 | ... P12: =IF(P$24=7,P$23,0) -> 0 | Q12: 0 | R12: =IF(R$24=7,R$23,0) -> 0 | S12: =IF(S$24=7,S$23,0) -> 0 | T12: =IF(T$24=7,T$23,0) -> 0 | U12: =IF(U$24=7,U$23,0) -> 0 | V12: =IF(V$24=7,V$23,0) -> 0 | W12: =IF(W$24=7,W$23,0) -> 0 | X12: =IF(X$24=7,X$23,0) -> 0 | Y12: =IF(Y$24=7,Y$23,0) -> 0 | ... BB12: =IF(BB$24=7,BB$23,0) -> 0 | BC12: =SUM(E12:BB12) -> 0
D13: CO8 | E13: =IF(E$24=8,E$23,0) -> 0 | F13: =IF(F$24=8,F$23,0) -> 0 | G13: =IF(G$24=8,G$23,0) -> 0 | H13: =IF(H$24=8,H$23,0) -> 0 | I13: =IF(I$24=8,I$23,0) -> 0 | J13: =IF(J$24=8,J$23,0) -> 0 | K13: =IF(K$24=8,K$23,0) -> 0 | L13: =IF(L$24=8,L$23,0) -> 0 | ... P13: =IF(P$24=8,P$23,0) -> 0 | Q13: 0 | R13: =IF(R$24=8,R$23,0) -> 0 | S13: =IF(S$24=8,S$23,0) -> 0 | T13: =IF(T$24=8,T$23,0) -> 0 | U13: =IF(U$24=8,U$23,0) -> 0 | V13: =IF(V$24=8,V$23,0) -> 0 | W13: =IF(W$24=8,W$23,0) -> 0 | X13: =IF(X$24=8,X$23,0) -> 0 | Y13: =IF(Y$24=8,Y$23,0) -> 0 | ... BB13: =IF(BB$24=8,BB$23,0) -> 0 | BC13: =SUM(E13:BB13) -> 0
D14: CO9 | E14: =IF(E$24=9,E$23,0) -> 0 | F14: =IF(F$24=9,F$23,0) -> 0 | G14: =IF(G$24=9,G$23,0) -> 0 | H14: =IF(H$24=9,H$23,0) -> 0 | I14: =IF(I$24=9,I$23,0) -> 0 | J14: =IF(J$24=9,J$23,0) -> 0 | K14: =IF(K$24=9,K$23,0) -> 0 | L14: =IF(L$24=9,L$23,0) -> 0 | ... P14: =IF(P$24=9,P$23,0) -> 0 | Q14: 0 | R14: =IF(R$24=9,R$23,0) -> 0 | S14: =IF(S$24=9,S$23,0) -> 0 | T14: =IF(T$24=9,T$23,0) -> 0 | U14: =IF(U$24=9,U$23,0) -> 0 | V14: =IF(V$24=9,V$23,0) -> 0 | W14: =IF(W$24=9,W$23,0) -> 0 | X14: =IF(X$24=9,X$23,0) -> 0 | Y14: =IF(Y$24=9,Y$23,0) -> 0 | ... BB14: =IF(BB$24=9,BB$23,0) -> 0 | BC14: =SUM(E14:BB14) -> 0
D15: CO10 | E15: =IF(E$24=10,E$23,0) -> 0 | F15: =IF(F$24=10,F$23,0) -> 0 | G15: =IF(G$24=10,G$23,0) -> 0 | H15: =IF(H$24=10,H$23,0) -> 0 | I15: =IF(I$24=10,I$23,0) -> 0 | J15: =IF(J$24=10,J$23,0) -> 0 | K15: =IF(K$24=10,K$23,0) -> 0 | L15: =IF(L$24=10,L$23,0) -> 0 | ... P15: =IF(P$24=10,P$23,0) -> 0 | Q15: 0 | R15: =IF(R$24=10,R$23,0) -> 0 | S15: =IF(S$24=10,S$23,0) -> 0 | T15: =IF(T$24=10,T$23,0) -> 0 | U15: =IF(U$24=10,U$23,0) -> 0 | V15: =IF(V$24=10,V$23,0) -> 0 | W15: =IF(W$24=10,W$23,0) -> 0 | X15: =IF(X$24=10,X$23,0) -> 0 | Y15: =IF(Y$24=10,Y$23,0) -> 0 | ... BB15: =IF(BB$24=10,BB$23,0) -> 0 | BC15: =SUM(E15:BB15) -> 0
D16: CO11 | E16: =IF(E$24=11,E$23,0) -> 0 | F16: =IF(F$24=11,F$23,0) -> 0 | G16: =IF(G$24=11,G$23,0) -> 0 | H16: =IF(H$24=11,H$23,0) -> 0 | I16: =IF(I$24=11,I$23,0) -> 0 | J16: =IF(J$24=11,J$23,0) -> 0 | K16: =IF(K$24=11,K$23,0) -> 0 | L16: =IF(L$24=11,L$23,0) -> 0 | ... P16: =IF(P$24=11,P$23,0) -> 0 | Q16: 0 | R16: =IF(R$24=11,R$23,0) -> 0 | S16: =IF(S$24=11,S$23,0) -> 0 | T16: =IF(T$24=11,T$23,0) -> 0 | U16: =IF(U$24=11,U$23,0) -> 0 | V16: =IF(V$24=11,V$23,0) -> 0 | W16: =IF(W$24=11,W$23,0) -> 0 | X16: =IF(X$24=11,X$23,0) -> 0 | Y16: =IF(Y$24=11,Y$23,0) -> 0 | ... BB16: =IF(BB$24=11,BB$23,0) -> 0 | BC16: =SUM(E16:BB16) -> 0
D17: CO12 | E17: =IF(E$24=12,E$23,0) -> 0 | F17: =IF(F$24=12,F$23,0) -> 0 | G17: =IF(G$24=12,G$23,0) -> 0 | H17: =IF(H$24=12,H$23,0) -> 0 | I17: =IF(I$24=12,I$23,0) -> 0 | J17: =IF(J$24=12,J$23,0) -> 0 | K17: =IF(K$24=12,K$23,0) -> 0 | L17: =IF(L$24=12,L$23,0) -> 0 | ... P17: =IF(P$24=12,P$23,0) -> 0 | Q17: 0 | R17: =IF(R$24=12,R$23,0) -> 0 | S17: =IF(S$24=12,S$23,0) -> 0 | T17: =IF(T$24=12,T$23,0) -> 0 | U17: =IF(U$24=12,U$23,0) -> 0 | V17: =IF(V$24=12,V$23,0) -> 0 | W17: =IF(W$24=12,W$23,0) -> 0 | X17: =IF(X$24=12,X$23,0) -> 0 | Y17: =IF(Y$24=12,Y$23,0) -> 0 | ... BB17: =IF(BB$24=12,BB$23,0) -> 0 | BC17: =SUM(E17:BB17) -> 0
D20: Assessment Type | E20: CP
D21: Description | E21: Assessment (60) | K21: Mid Term (90) | N21: Term Final (150)
E22: CT-1 | F22: CT-2 | G22: CT-3 | H22: Assignment | I22: Attendance | J22: Performace | K22: Q1 | L22: Q2 | M22: Q3 | N22: Q1 | O22: Q2 | P22: Q3 | Q22: Q4 | R22: Q5
D23: Maximum Marks | E23: 10 | F23: 10 | G23: 10 | H23: 10 | I23: 10 | J23: 10 | K23: 30 | L23: 30 | M23: 30 | N23: 30 | O23: 30 | P23: 30 | Q23: 30 | R23: 30 | BC23: =SUM(E23:BB23) -> 300 | BD23: Grade
D24: CO | E24: 1 | F24: 1 | G24: 2 | H24: 3 | J24: 2 | K24: 1 | L24: 4 | M24: 1 | N24: 1 | O24: 4 | P24: 1 | Q24: 2 | R24: 2
B26: Student Information
B27: * ID | C27: Name | D27: No. | E27: 1 | F27: 2 | G27: 3 | H27: 4 | I27: 5 | J27: 6 | K27: 7 | L27: 8 | M27: 9 | N27: 10 | O27: 11 | P27: 12 | Q27: 13 | R27: 14 | S27: 15 | T27: 16 | U27: 17 | V27: 18 | W27: 19 | X27: 20 | Y27: 21 | Z27: 22 | AA27: 23 | AB27: 24 | AC27: 25 | AD27: 26 | AE27: 27 | AF27: 28 | AG27: 29 | AH27: 30 | AI27: 31 | AJ27: 32 | AK27: 33 | AL27: 34 | AM27: 35 | AN27: 36 | AO27: 37 | AP27: 38 | AQ27: 39 | AR27: 40 | AS27: 41 | AT27: 42 | AU27: 43 | AV27: 44 | AW27: 45 | AX27: 46 | AY27: 47 | AZ27: 48 | BA27: 49 | BB27: 50
A28: 1 | B28: 1119002 | C28: Khandoker Fariya Afroje Naba | E28: 3 | F28: 7 | G28: 6 | H28: 7 | I28: 10 | J28: 10 | K28: 25 | L28: 25 | M28: 20 | N28: 30 | O28: 30 | P28: 25 | Q28: 27 | R28: 13 | BC28: =SUM(E28:K28) -> 68 | BD28: =IF(BC28>=80,"A+",IF(BC28>=75,"A",IF(BC28>=70,"A-",IF(BC28>=65,"B+",IF(BC28>=60,"B",IF(BC28>=55,"B-",IF(BC28>=50,"C+",IF(BC28>=45,"C",IF(BC28>=40,"D","F"))))))))) -> B+
A29: 2 | B29: 1119003 | C29: Md Najmus Sakib Rahatul | E29: 5 | F29: 4 | G29: 7 | H29: 8 | I29: 9 | J29: 10 | K29: 18 | L29: 22 | M29: 19 | N29: 10 | O29: 15 | P29: 30 | Q29: 20 | R29: 9 | BC29: =SUM(E29:K29) -> 61 | BD29: =IF(BC29>=80,"A+",IF(BC29>=75,"A",IF(BC29>=70,"A-",IF(BC29>=65,"B+",IF(BC29>=60,"B",IF(BC29>=55,"B-",IF(BC29>=50,"C+",IF(BC29>=45,"C",IF(BC29>=40,"D","F"))))))))) -> B
A30: 3 | B30: 1119004 | C30: Nesar Uddin Ifag | E30: 5 | F30: 6 | G30: 5 | H30: 8 | I30: 10 | J30: 10 | K30: 26 | L30: 23 | M30: 22 | N30: 23 | O30: 21 | P30: 22 | Q30: 23 | R30: 19 | BC30: =SUM(E30:K30) -> 70 | BD30: =IF(BC30>=80,"A+",IF(BC30>=75,"A",IF(BC30>=70,"A-",IF(BC30>=65,"B+",IF(BC30>=60,"B",IF(BC30>=55,"B-",IF(BC30>=50,"C+",IF(BC30>=45,"C",IF(BC30>=40,"D","F"))))))))) -> A-
A31: 4 | B31: 1119005 | C31: Musheu Hakim Firoz | E31: 7 | F31: 8 | G31: 7 | H31: 7 | I31: 10 | J31: 10 | K31: 27 | L31: 20 | M31: 22 | N31: 28 | O31: 15 | P31: 22 | Q31: 26 | R31: 29 | BC31: =SUM(E31:K31) -> 76 | BD31: =IF(BC31>=80,"A+",IF(BC31>=75,"A",IF(BC31>=70,"A-",IF(BC31>=65,"B+",IF(BC31>=60,"B",IF(BC31>=55,"B-",IF(BC31>=50,"C+",IF(BC31>=45,"C",IF(BC31>=40,"D","F"))))))))) -> A
A32: 5 | B32: 1119006 | C32: Sabrina Rahman Tisha | E32: 3 | F32: 5 | G32: 9 | H32: 7 | I32: 10 | J32: 10 | K32: 23 | L32: 13 | M32: 16 | N32: 22 | O32: 26 | P32: 10 | Q32: 29 | R32: 3 | BC32: =SUM(E32:K32) -> 67 | BD32: =IF(BC32>=80,"A+",IF(BC32>=75,"A",IF(BC32>=70,"A-",IF(BC32>=65,"B+",IF(BC32>=60,"B",IF(BC32>=55,"B-",IF(BC32>=50,"C+",IF(BC32>=45,"C",IF(BC32>=40,"D","F"))))))))) -> B+
A33: 6 | B33: 1119007 | C33: Rayhan Alam Towhid | E33: 6 | F33: 7 | G33: 5 | H33: 7 | I33: 10 | J33: 10 | K33: 16 | L33: 12 | M33: 13 | N33: 15 | O33: 18 | P33: 15 | Q33: 22 | R33: 10 | BC33: =SUM(E33:K33) -> 61 | BD33: =IF(BC33>=80,"A+",IF(BC33>=75,"A",IF(BC33>=70,"A-",IF(BC33>=65,"B+",IF(BC33>=60,"B",IF(BC33>=55,"B-",IF(BC33>=50,"C+",IF(BC33>=45,"C",IF(BC33>=40,"D","F"))))))))) -> B
A34: 7 | B34: 1119009 | C34: Salbina Nishat Suchi | E34: 7 | F34: 5 | G34: 7 | H34: 8 | I34: 10 | J34: 10 | K34: 18 | L34: 15 | M34: 20 | N34: 21 | O34: 25 | P34: 14 | Q34: 24 | R34: 16 | BC34: =SUM(E34:K34) -> 65 | BD34: =IF(BC34>=80,"A+",IF(BC34>=75,"A",IF(BC34>=70,"A-",IF(BC34>=65,"B+",IF(BC34>=60,"B",IF(BC34>=55,"B-",IF(BC34>=50,"C+",IF(BC34>=45,"C",IF(BC34>=40,"D","F"))))))))) -> B+
A35: 8 | B35: 1119010 | C35: Kazi Mahfuz Islam | E35: 5 | F35: 7 | G35: 8 | H35: 7 | I35: 9 | J35: 10 | K35: 26 | L35: 28 | M35: 23 | N35: 23 | O35: 27 | P35: 10 | Q35: 24 | R35: 22 | BC35: =SUM(E35:K35) -> 72 | BD35: =IF(BC35>=80,"A+",IF(BC35>=75,"A",IF(BC35>=70,"A-",IF(BC35>=65,"B+",IF(BC35>=60,"B",IF(BC35>=55,"B-",IF(BC35>=50,"C+",IF(BC35>=45,"C",IF(BC35>=40,"D","F"))))))))) -> A-
A36: 9 | B36: 1119013 | C36: Shedratul Muntaha Maisha | E36: 7 | F36: 8 | G36: 7 | H36: 10 | I36: 10 | J36: 10 | K36: 21 | L36: 27 | M36: 28 | N36: 20 | O36: 26 | P36: 24 | Q36: 23 | R36: 17 | BC36: =SUM(E36:K36) -> 73 | BD36: =IF(BC36>=80,"A+",IF(BC36>=75,"A",IF(BC36>=70,"A-",IF(BC36>=65,"B+",IF(BC36>=60,"B",IF(BC36>=55,"B-",IF(BC36>=50,"C+",IF(BC36>=45,"C",IF(BC36>=40,"D","F"))))))))) -> A-
A37: 10 | B37: 1119016 | C37: Sumiya Tasmi | E37: 9 | F37: 9 | H37: 8 | I37: 10 | J37: 10 | K37: 30 | L37: 27 | M37: 23 | N37: 30 | O37: 30 | P37: 26 | Q37: 28 | R37: 22 | BC37: =SUM(E37:K37) -> 76 | BD37: =IF(BC37>=80,"A+",IF(BC37>=75,"A",IF(BC37>=70,"A-",IF(BC37>=65,"B+",IF(BC37>=60,"B",IF(BC37>=55,"B-",IF(BC37>=50,"C+",IF(BC37>=45,"C",IF(BC37>=40,"D","F"))))))))) -> A
A38: 11 | B38: 1119017 | C38: Anika Bushra Lubna | E38: 8 | F38: 10 | G38: 8 | H38: 8 | I38: 10 | J38: 10 | K38: 27 | L38: 25 | M38: 6 | N38: 15 | O38: 27 | P38: 26 | Q38: 25 | R38: 20 | BC38: =SUM(E38:K38) -> 81 | BD38: =IF(BC38>=80,"A+",IF(BC38>=75,"A",IF(BC38>=70,"A-",IF(BC38>=65,"B+",IF(BC38>=60,"B",IF(BC38>=55,"B-",IF(BC38>=50,"C+",IF(BC38>=45,"C",IF(BC38>=40,"D","F"))))))))) -> A+
A39: 12 | B39: 1119018 | C39: Jannatul Ferdous | E39: 7 | F39: 10 | G39: 9 | H39: 10 | I39: 9 | J39: 10 | K39: 16 | L39: 30 | M39: 24 | N39: 30 | O39: 30 | P39: 24 | Q39: 23 | R39: 21 | BC39: =SUM(E39:K39) -> 71 | BD39: =IF(BC39>=80,"A+",IF(BC39>=75,"A",IF(BC39>=70,"A-",IF(BC39>=65,"B+",IF(BC39>=60,"B",IF(BC39>=55,"B-",IF(BC39>=50,"C+",IF(BC39>=45,"C",IF(BC39>=40,"D","F"))))))))) -> A-
A40: 13 | B40: 1119021 | C40: Israt Jahan Sweety | E40: 6 | F40: 8 | G40: 7 | H40: 10 | I40: 10 | J40: 10 | K40: 11 | L40: 22 | M40: 15 | N40: 20 | O40: 18 | P40: 16 | Q40: 16 | R40: 24 | BC40: =SUM(E40:K40) -> 62 | BD40: =IF(BC40>=80,"A+",IF(BC40>=75,"A",IF(BC40>=70,"A-",IF(BC40>=65,"B+",IF(BC40>=60,"B",IF(BC40>=55,"B-",IF(BC40>=50,"C+",IF(BC40>=45,"C",IF(BC40>=40,"D","F"))))))))) -> B
A41: 14 | B41: 1119022 | C41: Mosa Nusrat Jahan Ema | E41: 7 | F41: 8 | G41: 7 | H41: 7 | I41: 10 | J41: 10 | K41: 24 | L41: 21 | M41: 21 | N41: 23 | O41: 30 | P41: 23 | Q41: 21 | R41: 14 | BC41: =SUM(E41:K41) -> 73 | BD41: =IF(BC41>=80,"A+",IF(BC41>=75,"A",IF(BC41>=70,"A-",IF(BC41>=65,"B+",IF(BC41>=60,"B",IF(BC41>=55,"B-",IF(BC41>=50,"C+",IF(BC41>=45,"C",IF(BC41>=40,"D","F"))))))))) -> A-
A42: 15 | B42: 1119025 | C42: Robiul Hasan Rayhan | E42: 8 | F42: 10 | G42: 10 | H42: 8 | I42: 10 | J42: 10 | K42: 19 | L42: 13 | M42: 10 | N42: 6 | O42: 27 | P42: 10 | Q42: 24 | R42: 13 | BC42: =SUM(E42:K42) -> 75 | BD42: =IF(BC42>=80,"A+",IF(BC42>=75,"A",IF(BC42>=70,"A-",IF(BC42>=65,"B+",IF(BC42>=60,"B",IF(BC42>=55,"B-",IF(BC42>=50,"C+",IF(BC42>=45,"C",IF(BC42>=40,"D","F"))))))))) -> A
A43: 16 | B43: 1119026 | C43: Jahidul Alam Fahim | E43: 8 | F43: 0 | G43: 0 | H43: 10 | I43: 5 | J43: 10 | K43: 23 | L43: 25 | M43: 20 | N43: 21 | O43: 30 | P43: 28 | Q43: 28 | R43: 15 | BC43: =SUM(E43:K43) -> 56 | BD43: =IF(BC43>=80,"A+",IF(BC43>=75,"A",IF(BC43>=70,"A-",IF(BC43>=65,"B+",IF(BC43>=60,"B",IF(BC43>=55,"B-",IF(BC43>=50,"C+",IF(BC43>=45,"C",IF(BC43>=40,"D","F"))))))))) -> B-
A44: 17 | B44: 1119027 | C44: Sabera Subhani Himu | E44: 3 | F44: 10 | G44: 10 | H44: 9 | I44: 10 | J44: 10 | K44: 25 | L44: 25 | M44: 23 | N44: 28 | O44: 27 | P44: 27 | Q44: 26 | R44: 25 | BC44: =SUM(E44:K44) -> 77 | BD44: =IF(BC44>=80,"A+",IF(BC44>=75,"A",IF(BC44>=70,"A-",IF(BC44>=65,"B+",IF(BC44>=60,"B",IF(BC44>=55,"B-",IF(BC44>=50,"C+",IF(BC44>=45,"C",IF(BC44>=40,"D","F"))))))))) -> A
A45: 18 | B45: 1119028 | C45: Faria Islam | E45: 3 | F45: 6 | G45: 9 | H45: 9 | I45: 10 | J45: 10 | K45: 23 | L45: 25 | M45: 12 | N45: 25 | O45: 26 | P45: 20 | Q45: 30 | R45: 19 | BC45: =SUM(E45:K45) -> 70 | BD45: =IF(BC45>=80,"A+",IF(BC45>=75,"A",IF(BC45>=70,"A-",IF(BC45>=65,"B+",IF(BC45>=60,"B",IF(BC45>=55,"B-",IF(BC45>=50,"C+",IF(BC45>=45,"C",IF(BC45>=40,"D","F"))))))))) -> A-
...

Sheet COs-POs
A1: Calculations of COs & POs
A2: (Please only enter information in the yellow cells)
I4: Draft Calculation
B5: No. of Students | C5: =COUNTA(Marks!B28:B327) -> 31 | I5: std1 | J5: co1
J6: =((Marks!E28/IF(Marks!$E$23=0,0.00000001,Marks!$E$23))) -> 0.3 | K6: ((Marks!E27/IF(Marks!$E$22=0,0.00000001,Marks!$E$22)))
B7: Target Pass Marks | C7: 40 | J7: =(Marks!$E$6/Marks!$BC$6) -> 0.071428571 | K7: (Marks!$E$6/Marks!$BC$6)
J8: =((Marks!F28/IF(Marks!$F$23=0,0.00000001,Marks!$F$23)))*(Marks!$F$6/Marks!$BC$6)+((Marks!G28/IF(Marks!$G$23=0,0.00000001,Marks!$G$23)))*(Marks!$G$6/Marks!$BC$6)+((Marks!H28/IF(Marks!$H$23=0,0.00000001,Marks!$H$23)))*(Marks!$H$6/Marks!$BC$6) -> 0.05 | K8: ((Marks!F27/IF(Marks!$F$22=0,0.00000001,Marks!$F$22)))*(Marks!$F$6/Marks!$BC$6)+ ((Marks!G27/IF(Marks!$G$22=0,0.00000001,Marks!$G$22)))*(Marks!$G$6/Marks!$BC$6))
B9: Key Performance Indicator (KPI) | J9: =IF(Marks!$BC$6=0,0,(1))*100 -> 100
B10: KPI for COs | C10: 50
B11: KPI for POs | C11: 50
C14: CO1 | D14: CO2 | E14: CO3 | F14: CO4 | G14: CO5 | H14: CO6 | I14: CO7 | J14: CO8 | K14: CO9 | L14: CO10 | M14: CO11 | N14: CO12 | P14: PO1 | Q14: PO2 | R14: PO3 | S14: PO4 | T14: PO5 | U14: PO6 | V14: PO7 | W14: PO8 | X14: PO9 | Y14: PO10 | Z14: PO11 | AA14: PO12
B15: % considering Target Pass Marks | C15: =(COUNTIF(C19:C318,">"&$C$7)/$C$5)*100 -> 90.322581 | D15: =(COUNTIF(D19:D318,">"&$C$7)/$C$5)*100 -> 90.322581 | E15: =(COUNTIF(E19:E318,">"&$C$7)/$C$5)*100 -> 96.774194 | F15: =(COUNTIF(F19:F318,">"&$C$7)/$C$5)*100 -> 96.774194 | G15: =(COUNTIF(G19:G318,">"&$C$7)/$C$5)*100 -> 0 | H15: =(COUNTIF(H19:H318,">"&$C$7)/$C$5)*100 -> 0 | I15: =(COUNTIF(I19:I318,">"&$C$7)/$C$5)*100 -> 0 | J15: =(COUNTIF(J19:J318,">"&$C$7)/$C$5)*100 -> 0 | ... N15: =(COUNTIF(N19:N318,">"&$C$7)/$C$5)*100 -> 0 | P15: =(COUNTIF(P19:P318,">"&$C$7)/$C$5)*100 -> 90.322581 | Q15: =(COUNTIF(Q19:Q318,">"&$C$7)/$C$5)*100 -> 96.774194 | R15: =(COUNTIF(R19:R318,">"&$C$7)/$C$5)*100 -> 0 | S15: =(COUNTIF(S19:S318,">"&$C$7)/$C$5)*100 -> 0 | T15: =(COUNTIF(T19:T318,">"&$C$7)/$C$5)*100 -> 0 | U15: =(COUNTIF(U19:U318,">"&$C$7)/$C$5)*100 -> 0 | V15: =(COUNTIF(V19:V318,">"&$C$7)/$C$5)*100 -> 0 | W15: =(COUNTIF(W19:W318,">"&$C$7)/$C$5)*100 -> 0 | ... AA15: =(COUNTIF(AA19:AA318,">"&$C$7)/$C$5)*100 -> 0
B16: % considering KPI for CO | C16: =(COUNTIF(C19:C318,">"&$C$10)/$C$5)*100 -> 80.645161 | D16: =(COUNTIF(D19:D318,">"&$C$10)/$C$5)*100 -> 77.419355 | E16: =(COUNTIF(E19:E318,">"&$C$10)/$C$5)*100 -> 96.774194 | F16: =(COUNTIF(F19:F318,">"&$C$10)/$C$5)*100 -> 93.548387 | G16: =(COUNTIF(G19:G318,">"&$C$10)/$C$5)*100 -> 0 | H16: =(COUNTIF(H19:H318,">"&$C$10)/$C$5)*100 -> 0 | I16: =(COUNTIF(I19:I318,">"&$C$10)/$C$5)*100 -> 0 | J16: =(COUNTIF(J19:J318,">"&$C$10)/$C$5)*100 -> 0 | ... N16: =(COUNTIF(N19:N318,">"&$C$10)/$C$5)*100 -> 0 | P16: =(COUNTIF(P19:P318,">"&$C$11)/$C$5)*100 -> 80.645161 | Q16: =(COUNTIF(Q19:Q318,">"&$C$11)/$C$5)*100 -> 93.548387 | R16: =(COUNTIF(R19:R318,">"&$C$11)/$C$5)*100 -> 0 | S16: =(COUNTIF(S19:S318,">"&$C$11)/$C$5)*100 -> 0 | T16: =(COUNTIF(T19:T318,">"&$C$11)/$C$5)*100 -> 0 | U16: =(COUNTIF(U19:U318,">"&$C$11)/$C$5)*100 -> 0 | V16: =(COUNTIF(V19:V318,">"&$C$11)/$C$5)*100 -> 0 | W16: =(COUNTIF(W19:W318,">"&$C$11)/$C$5)*100 -> 0 | ... AA16: =(COUNTIF(AA19:AA318,">"&$C$11)/$C$5)*100 -> 0
B18: Student ID
